Workbook
Name Berlin_Feiertage: 'Listen'!$E$2:$E$82
Name MitarbeiterListe: 'Listen'!$B$2:$B$29
Name GewerkeListe: 'Listen'!$A$2:$A$13
Name Stundenexport_Druckbereich: 'Zeiterfassung Export'!$A$1:INDEX('Zeiterfassung Export'!$J:$J,MAX(5,IFERROR(MATCH(9.99999999999999E+307,'Zeiterfassung Export'!$K:$K),5)))
Name NUGewerkeListe: 'Listen'!$N$2:$N$8
Name LieferantenListe: 'Listen'!$P$2:$P$12
Name RechnungsartenListe: 'Listen'!$X$2:$X$4
Name ErfassungDatumListe: 'Listen'!$AB$2:$AB$367
Name ErfassungKWListe: 'Listen'!$AC$2:$AC$54

Sheet Projektübersicht
B2: BAUABLAUFMAPPE | N2: COCKPIT
B5: Projektsteuerung · Personal · Stunden · Material · Abrechnung
B7: PROJEKTSTAMMDATEN
B8: BAUVORHABEN | F8: GEWERKE
B10: PROJEKTVERANTWORTLICHER | F10: BAUBEGINN
B12: AUFTRAGGEBER | F12: BAUENDE
B15: PROJEKTCOCKPIT
B16: MARGE NACHUNTERNEHMER | F16: MARGE EIGENLEISTUNG | J16: PROJEKTMARGE TOTAL
B17: ='KPI-Basis'!$C$9 | F17: ='KPI-Basis'!$C$15 | J17: ='KPI-Basis'!$C$20
B19: ='Nachunternehmer'!$E$4
B21: STUNDEN SOLL | F21: STUNDEN IST | J21: RESTBUDGET STUNDEN
B22: 0 | F22: =SUM(Zeiterfassung!$H$6:$H$3665) | J22: =IF(B22="","",B22-F22)
N25: Kategorie | O25: Fakturiert | P25: Unfertige Leistungen | Q25: Restleistung
B26: PROJEKTFORTSCHRITT / AUFTRAGSVOLUMEN | N26: Auftragssumme | O26: =IF($B$28="",0,$F$28) | P26: =IF($B$28="",0,$J$28) | Q26: =IF($B$28="",0,MAX(0,$B$28-$F$28-$J$28))
B27: AUFTRAGSSUMME NETTO | F27: IN RECHNUNG GESTELLT | J27: UNFERTIGE LEISTUNGEN
B28: 0 | F28: =SUM(Rechnungsstand!$F$6:$F$305) | J28: ='Rechnungsstand'!$M$5
B30: Auftragssumme und Stunden-Soll werden im Cockpit gepflegt · Unfertige Leistungen werden im Rechnungsstand erfasst.

Sheet Zeiterfassung
A1: ZEITERFASSUNG · PROJEKTVERLAUF | L1: ← ZUM COCKPIT | O1: STUNDENEXPORT →
A3: Kalenderwochen und Tage automatisch aus Baubeginn/Bauende · Leistungen einmal je Tag erfassen · Mitarbeiterzeiten darunter dokumentieren | L3: SCHNELLNAVIGATION
A4: =IF('Projektübersicht'!B9="","BAUVORHABEN","BAUVORHABEN · "&'Projektübersicht'!B9) | D4: =IF('Projektübersicht'!B13="","AUFTRAGGEBER","AUFTRAGGEBER · "&'Projektübersicht'!B13) | G4: =IF(AND('Projektübersicht'!$F$11="",'Projektübersicht'!$F$13=""),"BAUZEIT",IF(OR('Projektübersicht'!$F$11="",'Projektübersicht'!$F$13=""),"BAUZEIT · Stammdaten unvollständig","BAUZEIT · "&TEXT(DAY('Projektübersicht'!$F$11),"00")&"."&TEXT(MONTH('Projektübersicht'!$F$11),"00")&"."&YEAR('Projektübersicht'!$F$11)&" – "&TEXT(DAY('Projektübersicht'!$F$13),"00")&"."&TEXT(MONTH('Projektübersicht'!$F$13),"00")&"."&YEAR('Projektübersicht'!$F$13))) | L4: DATUM | N4: =IF($M$4="","TAG AUSWÄHLEN",HYPERLINK("#'Zeiterfassung'!A"&(MATCH($M$4,$K$6:$K$3665,0)+5),"→ ZUM TAG"))
A5: KW | B5: DATUM | C5: TAG | D5: MITARBEITER | E5: GEWERK | F5: ARBEITSANFANG | G5: ARBEITSENDE | H5: ARBEITSSTUNDEN | I5: ARBEITEN / LEISTUNGEN DES TAGES | J5: TAGESBEMERKUNG | K5: DATUM INTERN | L5: KW | N5: =IF($M$5="","KW AUSWÄHLEN",HYPERLINK("#'Zeiterfassung'!A"&(MATCH($M$5,$A$6:$A$3665,0)+5),"→ ZUR KW"))
A6: =IF($K6="","",WEEKNUM($K6,21)) | B6: =IF($K6="","",$K6) | C6: =IF($K6="","",$K6) | H6: =IF(OR(F6="",G6=""),"",ROUND(MOD(G6-F6,1)*24,2)) | K6: =IF(OR('Projektübersicht'!$F$11="",'Projektübersicht'!$F$13="",'Projektübersicht'!$F$11>'Projektübersicht'!$F$13),"",IF(WORKDAY.INTL('Projektübersicht'!$F$11-1,1,"0000001")<='Projektübersicht'!$F$13,WORKDAY.INTL('Projektübersicht'!$F$11-1,1,"0000001"),""))
H7: =IF(OR(F7="",G7=""),"",ROUND(MOD(G7-F7,1)*24,2)) | K7: =IF(OR('Projektübersicht'!$F$11="",'Projektübersicht'!$F$13="",'Projektübersicht'!$F$11>'Projektübersicht'!$F$13),"",IF(WORKDAY.INTL('Projektübersicht'!$F$11-1,1,"0000001")<='Projektübersicht'!$F$13,WORKDAY.INTL('Projektübersicht'!$F$11-1,1,"0000001"),"")) | L7: MEHR ALS 5 MITARBEITER? Links am Tagesblock auf + klicken.
H8: =IF(OR(F8="",G8=""),"",ROUND(MOD(G8-F8,1)*24,2)) | K8: =IF(OR('Projektübersicht'!$F$11="",'Projektübersicht'!$F$13="",'Projektübersicht'!$F$11>'Projektübersicht'!$F$13),"",IF(WORKDAY.INTL('Projektübersicht'!$F$11-1,1,"0000001")<='Projektübersicht'!$F$13,WORKDAY.INTL('Projektübersicht'!$F$11-1,1,"0000001"),""))
H9: =IF(OR(F9="",G9=""),"",ROUND(MOD(G9-F9,1)*24,2)) | K9: =IF(OR('Projektübersicht'!$F$11="",'Projektübersicht'!$F$13="",'Projektübersicht'!$F$11>'Projektübersicht'!$F$13),"",IF(WORKDAY.INTL('Projektübersicht'!$F$11-1,1,"0000001")<='Projektübersicht'!$F$13,WORKDAY.INTL('Projektübersicht'!$F$11-1,1,"0000001"),""))
H10: =IF(OR(F10="",G10=""),"",ROUND(MOD(G10-F10,1)*24,2)) | K10: =IF(OR('Projektübersicht'!$F$11="",'Projektübersicht'!$F$13="",'Projektübersicht'!$F$11>'Projektübersicht'!$F$13),"",IF(WORKDAY.INTL('Projektübersicht'!$F$11-1,1,"0000001")<='Projektübersicht'!$F$13,WORKDAY.INTL('Projektübersicht'!$F$11-1,1,"0000001"),""))
H11: =IF(OR(F11="",G11=""),"",ROUND(MOD(G11-F11,1)*24,2)) | K11: =IF(OR('Projektübersicht'!$F$11="",'Projektübersicht'!$F$13="",'Projektübersicht'!$F$11>'Projektübersicht'!$F$13),"",IF(WORKDAY.INTL('Projektübersicht'!$F$11-1,1,"0000001")<='Projektübersicht'!$F$13,WORKDAY.INTL('Projektübersicht'!$F$11-1,1,"0000001"),""))
H12: =IF(OR(F12="",G12=""),"",ROUND(MOD(G12-F12,1)*24,2)) | K12: =IF(OR('Projektübersicht'!$F$11="",'Projektübersicht'!$F$13="",'Projektübersicht'!$F$11>'Projektübersicht'!$F$13),"",IF(WORKDAY.INTL('Projektübersicht'!$F$11-1,1,"0000001")<='Projektübersicht'!$F$13,WORKDAY.INTL('Projektübersicht'!$F$11-1,1,"0000001"),""))
H13: =IF(OR(F13="",G13=""),"",ROUND(MOD(G13-F13,1)*24,2)) | K13: =IF(OR('Projektübersicht'!$F$11="",'Projektübersicht'!$F$13="",'Projektübersicht'!$F$11>'Projektübersicht'!$F$13),"",IF(WORKDAY.INTL('Projektübersicht'!$F$11-1,1,"0000001")<='Projektübersicht'!$F$13,WORKDAY.INTL('Projektübersicht'!$F$11-1,1,"0000001"),""))
H14: =IF(OR(F14="",G14=""),"",ROUND(MOD(G14-F14,1)*24,2)) | K14: =IF(OR('Projektübersicht'!$F$11="",'Projektübersicht'!$F$13="",'Projektübersicht'!$F$11>'Projektübersicht'!$F$13),"",IF(WORKDAY.INTL('Projektübersicht'!$F$11-1,1,"0000001")<='Projektübersicht'!$F$13,WORKDAY.INTL('Projektübersicht'!$F$11-1,1,"0000001"),""))
H15: =IF(OR(F15="",G15=""),"",ROUND(MOD(G15-F15,1)*24,2)) | K15: =IF(OR('Projektübersicht'!$F$11="",'Projektübersicht'!$F$13="",'Projektübersicht'!$F$11>'Projektübersicht'!$F$13),"",IF(WORKDAY.INTL('Projektübersicht'!$F$11-1,1,"0000001")<='Projektübersicht'!$F$13,WORKDAY.INTL('Projektübersicht'!$F$11-1,1,"0000001"),""))
A16: =IF($K16="","",WEEKNUM($K16,21)) | B16: =IF($K16="","",$K16) | C16: =IF($K16="","",$K16) | H16: =IF(OR(F16="",G16=""),"",ROUND(MOD(G16-F16,1)*24,2)) | K16: =IF(OR('Projektübersicht'!$F$11="",'Projektübersicht'!$F$13="",'Projektübersicht'!$F$11>'Projektübersicht'!$F$13),"",IF(WORKDAY.INTL('Projektübersicht'!$F$11-1,2,"0000001")<='Projektübersicht'!$F$13,WORKDAY.INTL('Projektübersicht'!$F$11-1,2,"0000001"),""))
H17: =IF(OR(F17="",G17=""),"",ROUND(MOD(G17-F17,1)*24,2)) | K17: =IF(OR('Projektübersicht'!$F$11="",'Projektübersicht'!$F$13="",'Projektübersicht'!$F$11>'Projektübersicht'!$F$13),"",IF(WORKDAY.INTL('Projektübersicht'!$F$11-1,2,"0000001")<='Projektübersicht'!$F$13,WORKDAY.INTL('Projektübersicht'!$F$11-1,2,"0000001"),""))
H18: =IF(OR(F18="",G18=""),"",ROUND(MOD(G18-F18,1)*24,2)) | K18: =IF(OR('Projektübersicht'!$F$11="",'Projektübersicht'!$F$13="",'Projektübersicht'!$F$11>'Projektübersicht'!$F$13),"",IF(WORKDAY.INTL('Projektübersicht'!$F$11-1,2,"0000001")<='Projektübersicht'!$F$13,WORKDAY.INTL('Projektübersicht'!$F$11-1,2,"0000001"),""))
H19: =IF(OR(F19="",G19=""),"",ROUND(MOD(G19-F19,1)*24,2)) | K19: =IF(OR('Projektübersicht'!$F$11="",'Projektübersicht'!$F$13="",'Projektübersicht'!$F$11>'Projektübersicht'!$F$13),"",IF(WORKDAY.INTL('Projektübersicht'!$F$11-1,2,"0000001")<='Projektübersicht'!$F$13,WORKDAY.INTL('Projektübersicht'!$F$11-1,2,"0000001"),""))
H20: =IF(OR(F20="",G20=""),"",ROUND(MOD(G20-F20,1)*24,2)) | K20: =IF(OR('Projektübersicht'!$F$11="",'Projektübersicht'!$F$13="",'Projektübersicht'!$F$11>'Projektübersicht'!$F$13),"",IF(WORKDAY.INTL('Projektübersicht'!$F$11-1,2,"0000001")<='Projektübersicht'!$F$13,WORKDAY.INTL('Projektübersicht'!$F$11-1,2,"0000001"),""))
H21: =IF(OR(F21="",G21=""),"",ROUND(MOD(G21-F21,1)*24,2)) | K21: =IF(OR('Projektübersicht'!$F$11="",'Projektübersicht'!$F$13="",'Projektübersicht'!$F$11>'Projektübersicht'!$F$13),"",IF(WORKDAY.INTL('Projektübersicht'!$F$11-1,2,"0000001")<='Projektübersicht'!$F$13,WORKDAY.INTL('Projektübersicht'!$F$11-1,2,"0000001"),""))
H22: =IF(OR(F22="",G22=""),"",ROUND(MOD(G22-F22,1)*24,2)) | K22: =IF(OR('Projektübersicht'!$F$11="",'Projektübersicht'!$F$13="",'Projektübersicht'!$F$11>'Projektübersicht'!$F$13),"",IF(WORKDAY.INTL('Projektübersicht'!$F$11-1,2,"0000001")<='Projektübersicht'!$F$13,WORKDAY.INTL('Projektübersicht'!$F$11-1,2,"0000001"),""))
H23: =IF(OR(F23="",G23=""),"",ROUND(MOD(G23-F23,1)*24,2)) | K23: =IF(OR('Projektübersicht'!$F$11="",'Projektübersicht'!$F$13="",'Projektübersicht'!$F$11>'Projektübersicht'!$F$13),"",IF(WORKDAY.INTL('Projektübersicht'!$F$11-1,2,"0000001")<='Projektübersicht'!$F$13,WORKDAY.INTL('Projektübersicht'!$F$11-1,2,"0000001"),""))
H24: =IF(OR(F24="",G24=""),"",ROUND(MOD(G24-F24,1)*24,2)) | K24: =IF(OR('Projektübersicht'!$F$11="",'Projektübersicht'!$F$13="",'Projektübersicht'!$F$11>'Projektübersicht'!$F$13),"",IF(WORKDAY.INTL('Projektübersicht'!$F$11-1,2,"0000001")<='Projektübersicht'!$F$13,WORKDAY.INTL('Projektübersicht'!$F$11-1,2,"0000001"),""))
H25: =IF(OR(F25="",G25=""),"",ROUND(MOD(G25-F25,1)*24,2)) | K25: =IF(OR('Projektübersicht'!$F$11="",'Projektübersicht'!$F$13="",'Projektübersicht'!$F$11>'Projektübersicht'!$F$13),"",IF(WORKDAY.INTL('Projektübersicht'!$F$11-1,2,"0000001")<='Projektübersicht'!$F$13,WORKDAY.INTL('Projektübersicht'!$F$11-1,2,"0000001"),""))
A26: =IF($K26="","",WEEKNUM($K26,21)) | B26: =IF($K26="","",$K26) | C26: =IF($K26="","",$K26) | H26: =IF(OR(F26="",G26=""),"",ROUND(MOD(G26-F26,1)*24,2)) | K26: =IF(OR('Projektübersicht'!$F$11="",'Projektübersicht'!$F$13="",'Projektübersicht'!$F$11>'Projektübersicht'!$F$13),"",IF(WORKDAY.INTL('Projektübersicht'!$F$11-1,3,"0000001")<='Projektübersicht'!$F$13,WORKDAY.INTL('Projektübersicht'!$F$11-1,3,"0000001"),""))
H27: =IF(OR(F27="",G27=""),"",ROUND(MOD(G27-F27,1)*24,2)) | K27: =IF(OR('Projektübersicht'!$F$11="",'Projektübersicht'!$F$13="",'Projektübersicht'!$F$11>'Projektübersicht'!$F$13),"",IF(WORKDAY.INTL('Projektübersicht'!$F$11-1,3,"0000001")<='Projektübersicht'!$F$13,WORKDAY.INTL('Projektübersicht'!$F$11-1,3,"0000001"),""))
H28: =IF(OR(F28="",G28=""),"",ROUND(MOD(G28-F28,1)*24,2)) | K28: =IF(OR('Projektübersicht'!$F$11="",'Projektübersicht'!$F$13="",'Projektübersicht'!$F$11>'Projektübersicht'!$F$13),"",IF(WORKDAY.INTL('Projektübersicht'!$F$11-1,3,"0000001")<='Projektübersicht'!$F$13,WORKDAY.INTL('Projektübersicht'!$F$11-1,3,"0000001"),""))
H29: =IF(OR(F29="",G29=""),"",ROUND(MOD(G29-F29,1)*24,2)) | K29: =IF(OR('Projektübersicht'!$F$11="",'Projektübersicht'!$F$13="",'Projektübersicht'!$F$11>'Projektübersicht'!$F$13),"",IF(WORKDAY.INTL('Projektübersicht'!$F$11-1,3,"0000001")<='Projektübersicht'!$F$13,WORKDAY.INTL('Projektübersicht'!$F$11-1,3,"0000001"),""))
H30: =IF(OR(F30="",G30=""),"",ROUND(MOD(G30-F30,1)*24,2)) | K30: =IF(OR('Projektübersicht'!$F$11="",'Projektübersicht'!$F$13="",'Projektübersicht'!$F$11>'Projektübersicht'!$F$13),"",IF(WORKDAY.INTL('Projektübersicht'!$F$11-1,3,"0000001")<='Projektübersicht'!$F$13,WORKDAY.INTL('Projektübersicht'!$F$11-1,3,"0000001"),""))
H31: =IF(OR(F31="",G31=""),"",ROUND(MOD(G31-F31,1)*24,2)) | K31: =IF(OR('Projektübersicht'!$F$11="",'Projektübersicht'!$F$13="",'Projektübersicht'!$F$11>'Projektübersicht'!$F$13),"",IF(WORKDAY.INTL('Projektübersicht'!$F$11-1,3,"0000001")<='Projektübersicht'!$F$13,WORKDAY.INTL('Projektübersicht'!$F$11-1,3,"0000001"),""))
H32: =IF(OR(F32="",G32=""),"",ROUND(MOD(G32-F32,1)*24,2)) | K32: =IF(OR('Projektübersicht'!$F$11="",'Projektübersicht'!$F$13="",'Projektübersicht'!$F$11>'Projektübersicht'!$F$13),"",IF(WORKDAY.INTL('Projektübersicht'!$F$11-1,3,"0000001")<='Projektübersicht'!$F$13,WORKDAY.INTL('Projektübersicht'!$F$11-1,3,"0000001"),""))
H33: =IF(OR(F33="",G33=""),"",ROUND(MOD(G33-F33,1)*24,2)) | K33: =IF(OR('Projektübersicht'!$F$11="",'Projektübersicht'!$F$13="",'Projektübersicht'!$F$11>'Projektübersicht'!$F$13),"",IF(WORKDAY.INTL('Projektübersicht'!$F$11-1,3,"0000001")<='Projektübersicht'!$F$13,WORKDAY.INTL('Projektübersicht'!$F$11-1,3,"0000001"),""))
H34: =IF(OR(F34="",G34=""),"",ROUND(MOD(G34-F34,1)*24,2)) | K34: =IF(OR('Projektübersicht'!$F$11="",'Projektübersicht'!$F$13="",'Projektübersicht'!$F$11>'Projektübersicht'!$F$13),"",IF(WORKDAY.INTL('Projektübersicht'!$F$11-1,3,"0000001")<='Projektübersicht'!$F$13,WORKDAY.INTL('Projektübersicht'!$F$11-1,3,"0000001"),""))
H35: =IF(OR(F35="",G35=""),"",ROUND(MOD(G35-F35,1)*24,2)) | K35: =IF(OR('Projektübersicht'!$F$11="",'Projektübersicht'!$F$13="",'Projektübersicht'!$F$11>'Projektübersicht'!$F$13),"",IF(WORKDAY.INTL('Projektübersicht'!$F$11-1,3,"0000001")<='Projektübersicht'!$F$13,WORKDAY.INTL('Projektübersicht'!$F$11-1,3,"0000001"),""))
A36: =IF($K36="","",WEEKNUM($K36,21)) | B36: =IF($K36="","",$K36) | C36: =IF($K36="","",$K36) | H36: =IF(OR(F36="",G36=""),"",ROUND(MOD(G36-F36,1)*24,2)) | K36: =IF(OR('Projektübersicht'!$F$11="",'Projektübersicht'!$F$13="",'Projektübersicht'!$F$11>'Projektübersicht'!$F$13),"",IF(WORKDAY.INTL('Projektübersicht'!$F$11-1,4,"0000001")<='Projektübersicht'!$F$13,WORKDAY.INTL('Projektübersicht'!$F$11-1,4,"0000001"),""))
H37: =IF(OR(F37="",G37=""),"",ROUND(MOD(G37-F37,1)*24,2)) | K37: =IF(OR('Projektübersicht'!$F$11="",'Projektübersicht'!$F$13="",'Projektübersicht'!$F$11>'Projektübersicht'!$F$13),"",IF(WORKDAY.INTL('Projektübersicht'!$F$11-1,4,"0000001")<='Projektübersicht'!$F$13,WORKDAY.INTL('Projektübersicht'!$F$11-1,4,"0000001"),""))
H38: =IF(OR(F38="",G38=""),"",ROUND(MOD(G38-F38,1)*24,2)) | K38: =IF(OR('Projektübersicht'!$F$11="",'Projektübersicht'!$F$13="",'Projektübersicht'!$F$11>'Projektübersicht'!$F$13),"",IF(WORKDAY.INTL('Projektübersicht'!$F$11-1,4,"0000001")<='Projektübersicht'!$F$13,WORKDAY.INTL('Projektübersicht'!$F$11-1,4,"0000001"),""))
H39: =IF(OR(F39="",G39=""),"",ROUND(MOD(G39-F39,1)*24,2)) | K39: =IF(OR('Projektübersicht'!$F$11="",'Projektübersicht'!$F$13="",'Projektübersicht'!$F$11>'Projektübersicht'!$F$13),"",IF(WORKDAY.INTL('Projektübersicht'!$F$11-1,4,"0000001")<='Projektübersicht'!$F$13,WORKDAY.INTL('Projektübersicht'!$F$11-1,4,"0000001"),""))
H40: =IF(OR(F40="",G40=""),"",ROUND(MOD(G40-F40,1)*24,2)) | K40: =IF(OR('Projektübersicht'!$F$11="",'Projektübersicht'!$F$13="",'Projektübersicht'!$F$11>'Projektübersicht'!$F$13),"",IF(WORKDAY.INTL('Projektübersicht'!$F$11-1,4,"0000001")<='Projektübersicht'!$F$13,WORKDAY.INTL('Projektübersicht'!$F$11-1,4,"0000001"),""))
H41: =IF(OR(F41="",G41=""),"",ROUND(MOD(G41-F41,1)*24,2)) | K41: =IF(OR('Projektübersicht'!$F$11="",'Projektübersicht'!$F$13="",'Projektübersicht'!$F$11>'Projektübersicht'!$F$13),"",IF(WORKDAY.INTL('Projektübersicht'!$F$11-1,4,"0000001")<='Projektübersicht'!$F$13,WORKDAY.INTL('Projektübersicht'!$F$11-1,4,"0000001"),""))
...

Sheet Zeiterfassung Export
A1: ZEITERFASSUNG · EXPORT | L1: ← ZUM COCKPIT
A3: Hinweis: Der echte PDF-Export wird dynamisch aus der Zeiterfassung erzeugt (2 KW je Blatt, nur belegte Datensätze).
A4: =IF('Projektübersicht'!B9="","BAUVORHABEN","BAUVORHABEN · "&'Projektübersicht'!B9) | D4: =IF('Projektübersicht'!B13="","AUFTRAGGEBER","AUFTRAGGEBER · "&'Projektübersicht'!B13) | G4: =IF(AND('Projektübersicht'!$F$11="",'Projektübersicht'!$F$13=""),"BAUZEIT",IF(OR('Projektübersicht'!$F$11="",'Projektübersicht'!$F$13=""),"BAUZEIT · Stammdaten unvollständig","BAUZEIT · "&TEXT('Projektübersicht'!$F$11,"dd.mm.yyyy")&" – "&TEXT('Projektübersicht'!$F$13,"dd.mm.yyyy")))
A5: KW | B5: DATUM | C5: TAG | D5: MITARBEITER | E5: GEWERK | F5: ARBEITSANFANG | G5: ARBEITSENDE | H5: ARBEITSSTUNDEN | I5: ARBEITEN / LEISTUNGEN DES TAGES | J5: TAGESBEMERKUNG
A6: =IF($K6="","",WEEKNUM(INDEX(Zeiterfassung!$K$6:$K$3665,$K6),21)) | B6: =IF($K6="","",INDEX(Zeiterfassung!$K$6:$K$3665,$K6)) | C6: =IF($K6="","",INDEX(Zeiterfassung!$K$6:$K$3665,$K6)) | D6: =IF($K6="","",INDEX(Zeiterfassung!$D$6:$D$3665,$K6)) | E6: =IF($K6="","",INDEX(Zeiterfassung!$E$6:$E$3665,$K6)) | F6: =IF($K6="","",INDEX(Zeiterfassung!$F$6:$F$3665,$K6)) | G6: =IF($K6="","",INDEX(Zeiterfassung!$G$6:$G$3665,$K6)) | H6: =IF($K6="","",INDEX(Zeiterfassung!$H$6:$H$3665,$K6)) | I6: =IF($K6="","",INDEX(Zeiterfassung!$I$6:$I$3665,MATCH(INDEX(Zeiterfassung!$K$6:$K$3665,$K6),Zeiterfassung!$K$6:$K$3665,0))) | J6: =IF($K6="","",INDEX(Zeiterfassung!$J$6:$J$3665,MATCH(INDEX(Zeiterfassung!$K$6:$K$3665,$K6),Zeiterfassung!$K$6:$K$3665,0))) | K6: =IFERROR(AGGREGATE(15,6,(ROW(Zeiterfassung!$D$6:$D$3665)-ROW(Zeiterfassung!$D$6)+1)/(Zeiterfassung!$D$6:$D$3665<>""),1),"")
A7: =IF($K7="","",WEEKNUM(INDEX(Zeiterfassung!$K$6:$K$3665,$K7),21)) | B7: =IF($K7="","",INDEX(Zeiterfassung!$K$6:$K$3665,$K7)) | C7: =IF($K7="","",INDEX(Zeiterfassung!$K$6:$K$3665,$K7)) | D7: =IF($K7="","",INDEX(Zeiterfassung!$D$6:$D$3665,$K7)) | E7: =IF($K7="","",INDEX(Zeiterfassung!$E$6:$E$3665,$K7)) | F7: =IF($K7="","",INDEX(Zeiterfassung!$F$6:$F$3665,$K7)) | G7: =IF($K7="","",INDEX(Zeiterfassung!$G$6:$G$3665,$K7)) | H7: =IF($K7="","",INDEX(Zeiterfassung!$H$6:$H$3665,$K7)) | I7: =IF(B7=B6,"",IF($K7="","",INDEX(Zeiterfassung!$I$6:$I$3665,MATCH(INDEX(Zeiterfassung!$K$6:$K$3665,$K7),Zeiterfassung!$K$6:$K$3665,0)))) | J7: =IF(B7=B6,"",IF($K7="","",INDEX(Zeiterfassung!$J$6:$J$3665,MATCH(INDEX(Zeiterfassung!$K$6:$K$3665,$K7),Zeiterfassung!$K$6:$K$3665,0)))) | K7: =IFERROR(AGGREGATE(15,6,(ROW(Zeiterfassung!$D$6:$D$3665)-ROW(Zeiterfassung!$D$6)+1)/(Zeiterfassung!$D$6:$D$3665<>""),2),"")
A8: =IF($K8="","",WEEKNUM(INDEX(Zeiterfassung!$K$6:$K$3665,$K8),21)) | B8: =IF($K8="","",INDEX(Zeiterfassung!$K$6:$K$3665,$K8)) | C8: =IF($K8="","",INDEX(Zeiterfassung!$K$6:$K$3665,$K8)) | D8: =IF($K8="","",INDEX(Zeiterfassung!$D$6:$D$3665,$K8)) | E8: =IF($K8="","",INDEX(Zeiterfassung!$E$6:$E$3665,$K8)) | F8: =IF($K8="","",INDEX(Zeiterfassung!$F$6:$F$3665,$K8)) | G8: =IF($K8="","",INDEX(Zeiterfassung!$G$6:$G$3665,$K8)) | H8: =IF($K8="","",INDEX(Zeiterfassung!$H$6:$H$3665,$K8)) | I8: =IF(B8=B7,"",IF($K8="","",INDEX(Zeiterfassung!$I$6:$I$3665,MATCH(INDEX(Zeiterfassung!$K$6:$K$3665,$K8),Zeiterfassung!$K$6:$K$3665,0)))) | J8: =IF(B8=B7,"",IF($K8="","",INDEX(Zeiterfassung!$J$6:$J$3665,MATCH(INDEX(Zeiterfassung!$K$6:$K$3665,$K8),Zeiterfassung!$K$6:$K$3665,0)))) | K8: =IFERROR(AGGREGATE(15,6,(ROW(Zeiterfassung!$D$6:$D$3665)-ROW(Zeiterfassung!$D$6)+1)/(Zeiterfassung!$D$6:$D$3665<>""),3),"")
A9: =IF($K9="","",WEEKNUM(INDEX(Zeiterfassung!$K$6:$K$3665,$K9),21)) | B9: =IF($K9="","",INDEX(Zeiterfassung!$K$6:$K$3665,$K9)) | C9: =IF($K9="","",INDEX(Zeiterfassung!$K$6:$K$3665,$K9)) | D9: =IF($K9="","",INDEX(Zeiterfassung!$D$6:$D$3665,$K9)) | E9: =IF($K9="","",INDEX(Zeiterfassung!$E$6:$E$3665,$K9)) | F9: =IF($K9="","",INDEX(Zeiterfassung!$F$6:$F$3665,$K9)) | G9: =IF($K9="","",INDEX(Zeiterfassung!$G$6:$G$3665,$K9)) | H9: =IF($K9="","",INDEX(Zeiterfassung!$H$6:$H$3665,$K9)) | I9: =IF(B9=B8,"",IF($K9="","",INDEX(Zeiterfassung!$I$6:$I$3665,MATCH(INDEX(Zeiterfassung!$K$6:$K$3665,$K9),Zeiterfassung!$K$6:$K$3665,0)))) | J9: =IF(B9=B8,"",IF($K9="","",INDEX(Zeiterfassung!$J$6:$J$3665,MATCH(INDEX(Zeiterfassung!$K$6:$K$3665,$K9),Zeiterfassung!$K$6:$K$3665,0)))) | K9: =IFERROR(AGGREGATE(15,6,(ROW(Zeiterfassung!$D$6:$D$3665)-ROW(Zeiterfassung!$D$6)+1)/(Zeiterfassung!$D$6:$D$3665<>""),4),"")
A10: =IF($K10="","",WEEKNUM(INDEX(Zeiterfassung!$K$6:$K$3665,$K10),21)) | B10: =IF($K10="","",INDEX(Zeiterfassung!$K$6:$K$3665,$K10)) | C10: =IF($K10="","",INDEX(Zeiterfassung!$K$6:$K$3665,$K10)) | D10: =IF($K10="","",INDEX(Zeiterfassung!$D$6:$D$3665,$K10)) | E10: =IF($K10="","",INDEX(Zeiterfassung!$E$6:$E$3665,$K10)) | F10: =IF($K10="","",INDEX(Zeiterfassung!$F$6:$F$3665,$K10)) | G10: =IF($K10="","",INDEX(Zeiterfassung!$G$6:$G$3665,$K10)) | H10: =IF($K10="","",INDEX(Zeiterfassung!$H$6:$H$3665,$K10)) | I10: =IF(B10=B9,"",IF($K10="","",INDEX(Zeiterfassung!$I$6:$I$3665,MATCH(INDEX(Zeiterfassung!$K$6:$K$3665,$K10),Zeiterfassung!$K$6:$K$3665,0)))) | J10: =IF(B10=B9,"",IF($K10="","",INDEX(Zeiterfassung!$J$6:$J$3665,MATCH(INDEX(Zeiterfassung!$K$6:$K$3665,$K10),Zeiterfassung!$K$6:$K$3665,0)))) | K10: =IFERROR(AGGREGATE(15,6,(ROW(Zeiterfassung!$D$6:$D$3665)-ROW(Zeiterfassung!$D$6)+1)/(Zeiterfassung!$D$6:$D$3665<>""),5),"")
A11: =IF($K11="","",WEEKNUM(INDEX(Zeiterfassung!$K$6:$K$3665,$K11),21)) | B11: =IF($K11="","",INDEX(Zeiterfassung!$K$6:$K$3665,$K11)) | C11: =IF($K11="","",INDEX(Zeiterfassung!$K$6:$K$3665,$K11)) | D11: =IF($K11="","",INDEX(Zeiterfassung!$D$6:$D$3665,$K11)) | E11: =IF($K11="","",INDEX(Zeiterfassung!$E$6:$E$3665,$K11)) | F11: =IF($K11="","",INDEX(Zeiterfassung!$F$6:$F$3665,$K11)) | G11: =IF($K11="","",INDEX(Zeiterfassung!$G$6:$G$3665,$K11)) | H11: =IF($K11="","",INDEX(Zeiterfassung!$H$6:$H$3665,$K11)) | I11: =IF(B11=B10,"",IF($K11="","",INDEX(Zeiterfassung!$I$6:$I$3665,MATCH(INDEX(Zeiterfassung!$K$6:$K$3665,$K11),Zeiterfassung!$K$6:$K$3665,0)))) | J11: =IF(B11=B10,"",IF($K11="","",INDEX(Zeiterfassung!$J$6:$J$3665,MATCH(INDEX(Zeiterfassung!$K$6:$K$3665,$K11),Zeiterfassung!$K$6:$K$3665,0)))) | K11: =IFERROR(AGGREGATE(15,6,(ROW(Zeiterfassung!$D$6:$D$3665)-ROW(Zeiterfassung!$D$6)+1)/(Zeiterfassung!$D$6:$D$3665<>""),6),"")
A12: =IF($K12="","",WEEKNUM(INDEX(Zeiterfassung!$K$6:$K$3665,$K12),21)) | B12: =IF($K12="","",INDEX(Zeiterfassung!$K$6:$K$3665,$K12)) | C12: =IF($K12="","",INDEX(Zeiterfassung!$K$6:$K$3665,$K12)) | D12: =IF($K12="","",INDEX(Zeiterfassung!$D$6:$D$3665,$K12)) | E12: =IF($K12="","",INDEX(Zeiterfassung!$E$6:$E$3665,$K12)) | F12: =IF($K12="","",INDEX(Zeiterfassung!$F$6:$F$3665,$K12)) | G12: =IF($K12="","",INDEX(Zeiterfassung!$G$6:$G$3665,$K12)) | H12: =IF($K12="","",INDEX(Zeiterfassung!$H$6:$H$3665,$K12)) | I12: =IF(B12=B11,"",IF($K12="","",INDEX(Zeiterfassung!$I$6:$I$3665,MATCH(INDEX(Zeiterfassung!$K$6:$K$3665,$K12),Zeiterfassung!$K$6:$K$3665,0)))) | J12: =IF(B12=B11,"",IF($K12="","",INDEX(Zeiterfassung!$J$6:$J$3665,MATCH(INDEX(Zeiterfassung!$K$6:$K$3665,$K12),Zeiterfassung!$K$6:$K$3665,0)))) | K12: =IFERROR(AGGREGATE(15,6,(ROW(Zeiterfassung!$D$6:$D$3665)-ROW(Zeiterfassung!$D$6)+1)/(Zeiterfassung!$D$6:$D$3665<>""),7),"")
A13: =IF($K13="","",WEEKNUM(INDEX(Zeiterfassung!$K$6:$K$3665,$K13),21)) | B13: =IF($K13="","",INDEX(Zeiterfassung!$K$6:$K$3665,$K13)) | C13: =IF($K13="","",INDEX(Zeiterfassung!$K$6:$K$3665,$K13)) | D13: =IF($K13="","",INDEX(Zeiterfassung!$D$6:$D$3665,$K13)) | E13: =IF($K13="","",INDEX(Zeiterfassung!$E$6:$E$3665,$K13)) | F13: =IF($K13="","",INDEX(Zeiterfassung!$F$6:$F$3665,$K13)) | G13: =IF($K13="","",INDEX(Zeiterfassung!$G$6:$G$3665,$K13)) | H13: =IF($K13="","",INDEX(Zeiterfassung!$H$6:$H$3665,$K13)) | I13: =IF(B13=B12,"",IF($K13="","",INDEX(Zeiterfassung!$I$6:$I$3665,MATCH(INDEX(Zeiterfassung!$K$6:$K$3665,$K13),Zeiterfassung!$K$6:$K$3665,0)))) | J13: =IF(B13=B12,"",IF($K13="","",INDEX(Zeiterfassung!$J$6:$J$3665,MATCH(INDEX(Zeiterfassung!$K$6:$K$3665,$K13),Zeiterfassung!$K$6:$K$3665,0)))) | K13: =IFERROR(AGGREGATE(15,6,(ROW(Zeiterfassung!$D$6:$D$3665)-ROW(Zeiterfassung!$D$6)+1)/(Zeiterfassung!$D$6:$D$3665<>""),8),"")
A14: =IF($K14="","",WEEKNUM(INDEX(Zeiterfassung!$K$6:$K$3665,$K14),21)) | B14: =IF($K14="","",INDEX(Zeiterfassung!$K$6:$K$3665,$K14)) | C14: =IF($K14="","",INDEX(Zeiterfassung!$K$6:$K$3665,$K14)) | D14: =IF($K14="","",INDEX(Zeiterfassung!$D$6:$D$3665,$K14)) | E14: =IF($K14="","",INDEX(Zeiterfassung!$E$6:$E$3665,$K14)) | F14: =IF($K14="","",INDEX(Zeiterfassung!$F$6:$F$3665,$K14)) | G14: =IF($K14="","",INDEX(Zeiterfassung!$G$6:$G$3665,$K14)) | H14: =IF($K14="","",INDEX(Zeiterfassung!$H$6:$H$3665,$K14)) | I14: =IF(B14=B13,"",IF($K14="","",INDEX(Zeiterfassung!$I$6:$I$3665,MATCH(INDEX(Zeiterfassung!$K$6:$K$3665,$K14),Zeiterfassung!$K$6:$K$3665,0)))) | J14: =IF(B14=B13,"",IF($K14="","",INDEX(Zeiterfassung!$J$6:$J$3665,MATCH(INDEX(Zeiterfassung!$K$6:$K$3665,$K14),Zeiterfassung!$K$6:$K$3665,0)))) | K14: =IFERROR(AGGREGATE(15,6,(ROW(Zeiterfassung!$D$6:$D$3665)-ROW(Zeiterfassung!$D$6)+1)/(Zeiterfassung!$D$6:$D$3665<>""),9),"")
A15: =IF($K15="","",WEEKNUM(INDEX(Zeiterfassung!$K$6:$K$3665,$K15),21)) | B15: =IF($K15="","",INDEX(Zeiterfassung!$K$6:$K$3665,$K15)) | C15: =IF($K15="","",INDEX(Zeiterfassung!$K$6:$K$3665,$K15)) | D15: =IF($K15="","",INDEX(Zeiterfassung!$D$6:$D$3665,$K15)) | E15: =IF($K15="","",INDEX(Zeiterfassung!$E$6:$E$3665,$K15)) | F15: =IF($K15="","",INDEX(Zeiterfassung!$F$6:$F$3665,$K15)) | G15: =IF($K15="","",INDEX(Zeiterfassung!$G$6:$G$3665,$K15)) | H15: =IF($K15="","",INDEX(Zeiterfassung!$H$6:$H$3665,$K15)) | I15: =IF(B15=B14,"",IF($K15="","",INDEX(Zeiterfassung!$I$6:$I$3665,MATCH(INDEX(Zeiterfassung!$K$6:$K$3665,$K15),Zeiterfassung!$K$6:$K$3665,0)))) | J15: =IF(B15=B14,"",IF($K15="","",INDEX(Zeiterfassung!$J$6:$J$3665,MATCH(INDEX(Zeiterfassung!$K$6:$K$3665,$K15),Zeiterfassung!$K$6:$K$3665,0)))) | K15: =IFERROR(AGGREGATE(15,6,(ROW(Zeiterfassung!$D$6:$D$3665)-ROW(Zeiterfassung!$D$6)+1)/(Zeiterfassung!$D$6:$D$3665<>""),10),"")
A16: =IF($K16="","",WEEKNUM(INDEX(Zeiterfassung!$K$6:$K$3665,$K16),21)) | B16: =IF($K16="","",INDEX(Zeiterfassung!$K$6:$K$3665,$K16)) | C16: =IF($K16="","",INDEX(Zeiterfassung!$K$6:$K$3665,$K16)) | D16: =IF($K16="","",INDEX(Zeiterfassung!$D$6:$D$3665,$K16)) | E16: =IF($K16="","",INDEX(Zeiterfassung!$E$6:$E$3665,$K16)) | F16: =IF($K16="","",INDEX(Zeiterfassung!$F$6:$F$3665,$K16)) | G16: =IF($K16="","",INDEX(Zeiterfassung!$G$6:$G$3665,$K16)) | H16: =IF($K16="","",INDEX(Zeiterfassung!$H$6:$H$3665,$K16)) | I16: =IF(B16=B15,"",IF($K16="","",INDEX(Zeiterfassung!$I$6:$I$3665,MATCH(INDEX(Zeiterfassung!$K$6:$K$3665,$K16),Zeiterfassung!$K$6:$K$3665,0)))) | J16: =IF(B16=B15,"",IF($K16="","",INDEX(Zeiterfassung!$J$6:$J$3665,MATCH(INDEX(Zeiterfassung!$K$6:$K$3665,$K16),Zeiterfassung!$K$6:$K$3665,0)))) | K16: =IFERROR(AGGREGATE(15,6,(ROW(Zeiterfassung!$D$6:$D$3665)-ROW(Zeiterfassung!$D$6)+1)/(Zeiterfassung!$D$6:$D$3665<>""),11),"")
A17: =IF($K17="","",WEEKNUM(INDEX(Zeiterfassung!$K$6:$K$3665,$K17),21)) | B17: =IF($K17="","",INDEX(Zeiterfassung!$K$6:$K$3665,$K17)) | C17: =IF($K17="","",INDEX(Zeiterfassung!$K$6:$K$3665,$K17)) | D17: =IF($K17="","",INDEX(Zeiterfassung!$D$6:$D$3665,$K17)) | E17: =IF($K17="","",INDEX(Zeiterfassung!$E$6:$E$3665,$K17)) | F17: =IF($K17="","",INDEX(Zeiterfassung!$F$6:$F$3665,$K17)) | G17: =IF($K17="","",INDEX(Zeiterfassung!$G$6:$G$3665,$K17)) | H17: =IF($K17="","",INDEX(Zeiterfassung!$H$6:$H$3665,$K17)) | I17: =IF(B17=B16,"",IF($K17="","",INDEX(Zeiterfassung!$I$6:$I$3665,MATCH(INDEX(Zeiterfassung!$K$6:$K$3665,$K17),Zeiterfassung!$K$6:$K$3665,0)))) | J17: =IF(B17=B16,"",IF($K17="","",INDEX(Zeiterfassung!$J$6:$J$3665,MATCH(INDEX(Zeiterfassung!$K$6:$K$3665,$K17),Zeiterfassung!$K$6:$K$3665,0)))) | K17: =IFERROR(AGGREGATE(15,6,(ROW(Zeiterfassung!$D$6:$D$3665)-ROW(Zeiterfassung!$D$6)+1)/(Zeiterfassung!$D$6:$D$3665<>""),12),"")
A18: =IF($K18="","",WEEKNUM(INDEX(Zeiterfassung!$K$6:$K$3665,$K18),21)) | B18: =IF($K18="","",INDEX(Zeiterfassung!$K$6:$K$3665,$K18)) | C18: =IF($K18="","",INDEX(Zeiterfassung!$K$6:$K$3665,$K18)) | D18: =IF($K18="","",INDEX(Zeiterfassung!$D$6:$D$3665,$K18)) | E18: =IF($K18="","",INDEX(Zeiterfassung!$E$6:$E$3665,$K18)) | F18: =IF($K18="","",INDEX(Zeiterfassung!$F$6:$F$3665,$K18)) | G18: =IF($K18="","",INDEX(Zeiterfassung!$G$6:$G$3665,$K18)) | H18: =IF($K18="","",INDEX(Zeiterfassung!$H$6:$H$3665,$K18)) | I18: =IF(B18=B17,"",IF($K18="","",INDEX(Zeiterfassung!$I$6:$I$3665,MATCH(INDEX(Zeiterfassung!$K$6:$K$3665,$K18),Zeiterfassung!$K$6:$K$3665,0)))) | J18: =IF(B18=B17,"",IF($K18="","",INDEX(Zeiterfassung!$J$6:$J$3665,MATCH(INDEX(Zeiterfassung!$K$6:$K$3665,$K18),Zeiterfassung!$K$6:$K$3665,0)))) | K18: =IFERROR(AGGREGATE(15,6,(ROW(Zeiterfassung!$D$6:$D$3665)-ROW(Zeiterfassung!$D$6)+1)/(Zeiterfassung!$D$6:$D$3665<>""),13),"")
A19: =IF($K19="","",WEEKNUM(INDEX(Zeiterfassung!$K$6:$K$3665,$K19),21)) | B19: =IF($K19="","",INDEX(Zeiterfassung!$K$6:$K$3665,$K19)) | C19: =IF($K19="","",INDEX(Zeiterfassung!$K$6:$K$3665,$K19)) | D19: =IF($K19="","",INDEX(Zeiterfassung!$D$6:$D$3665,$K19)) | E19: =IF($K19="","",INDEX(Zeiterfassung!$E$6:$E$3665,$K19)) | F19: =IF($K19="","",INDEX(Zeiterfassung!$F$6:$F$3665,$K19)) | G19: =IF($K19="","",INDEX(Zeiterfassung!$G$6:$G$3665,$K19)) | H19: =IF($K19="","",INDEX(Zeiterfassung!$H$6:$H$3665,$K19)) | I19: =IF(B19=B18,"",IF($K19="","",INDEX(Zeiterfassung!$I$6:$I$3665,MATCH(INDEX(Zeiterfassung!$K$6:$K$3665,$K19),Zeiterfassung!$K$6:$K$3665,0)))) | J19: =IF(B19=B18,"",IF($K19="","",INDEX(Zeiterfassung!$J$6:$J$3665,MATCH(INDEX(Zeiterfassung!$K$6:$K$3665,$K19),Zeiterfassung!$K$6:$K$3665,0)))) | K19: =IFERROR(AGGREGATE(15,6,(ROW(Zeiterfassung!$D$6:$D$3665)-ROW(Zeiterfassung!$D$6)+1)/(Zeiterfassung!$D$6:$D$3665<>""),14),"")
A20: =IF($K20="","",WEEKNUM(INDEX(Zeiterfassung!$K$6:$K$3665,$K20),21)) | B20: =IF($K20="","",INDEX(Zeiterfassung!$K$6:$K$3665,$K20)) | C20: =IF($K20="","",INDEX(Zeiterfassung!$K$6:$K$3665,$K20)) | D20: =IF($K20="","",INDEX(Zeiterfassung!$D$6:$D$3665,$K20)) | E20: =IF($K20="","",INDEX(Zeiterfassung!$E$6:$E$3665,$K20)) | F20: =IF($K20="","",INDEX(Zeiterfassung!$F$6:$F$3665,$K20)) | G20: =IF($K20="","",INDEX(Zeiterfassung!$G$6:$G$3665,$K20)) | H20: =IF($K20="","",INDEX(Zeiterfassung!$H$6:$H$3665,$K20)) | I20: =IF(B20=B19,"",IF($K20="","",INDEX(Zeiterfassung!$I$6:$I$3665,MATCH(INDEX(Zeiterfassung!$K$6:$K$3665,$K20),Zeiterfassung!$K$6:$K$3665,0)))) | J20: =IF(B20=B19,"",IF($K20="","",INDEX(Zeiterfassung!$J$6:$J$3665,MATCH(INDEX(Zeiterfassung!$K$6:$K$3665,$K20),Zeiterfassung!$K$6:$K$3665,0)))) | K20: =IFERROR(AGGREGATE(15,6,(ROW(Zeiterfassung!$D$6:$D$3665)-ROW(Zeiterfassung!$D$6)+1)/(Zeiterfassung!$D$6:$D$3665<>""),15),"")
A21: =IF($K21="","",WEEKNUM(INDEX(Zeiterfassung!$K$6:$K$3665,$K21),21)) | B21: =IF($K21="","",INDEX(Zeiterfassung!$K$6:$K$3665,$K21)) | C21: =IF($K21="","",INDEX(Zeiterfassung!$K$6:$K$3665,$K21)) | D21: =IF($K21="","",INDEX(Zeiterfassung!$D$6:$D$3665,$K21)) | E21: =IF($K21="","",INDEX(Zeiterfassung!$E$6:$E$3665,$K21)) | F21: =IF($K21="","",INDEX(Zeiterfassung!$F$6:$F$3665,$K21)) | G21: =IF($K21="","",INDEX(Zeiterfassung!$G$6:$G$3665,$K21)) | H21: =IF($K21="","",INDEX(Zeiterfassung!$H$6:$H$3665,$K21)) | I21: =IF(B21=B20,"",IF($K21="","",INDEX(Zeiterfassung!$I$6:$I$3665,MATCH(INDEX(Zeiterfassung!$K$6:$K$3665,$K21),Zeiterfassung!$K$6:$K$3665,0)))) | J21: =IF(B21=B20,"",IF($K21="","",INDEX(Zeiterfassung!$J$6:$J$3665,MATCH(INDEX(Zeiterfassung!$K$6:$K$3665,$K21),Zeiterfassung!$K$6:$K$3665,0)))) | K21: =IFERROR(AGGREGATE(15,6,(ROW(Zeiterfassung!$D$6:$D$3665)-ROW(Zeiterfassung!$D$6)+1)/(Zeiterfassung!$D$6:$D$3665<>""),16),"")
A22: =IF($K22="","",WEEKNUM(INDEX(Zeiterfassung!$K$6:$K$3665,$K22),21)) | B22: =IF($K22="","",INDEX(Zeiterfassung!$K$6:$K$3665,$K22)) | C22: =IF($K22="","",INDEX(Zeiterfassung!$K$6:$K$3665,$K22)) | D22: =IF($K22="","",INDEX(Zeiterfassung!$D$6:$D$3665,$K22)) | E22: =IF($K22="","",INDEX(Zeiterfassung!$E$6:$E$3665,$K22)) | F22: =IF($K22="","",INDEX(Zeiterfassung!$F$6:$F$3665,$K22)) | G22: =IF($K22="","",INDEX(Zeiterfassung!$G$6:$G$3665,$K22)) | H22: =IF($K22="","",INDEX(Zeiterfassung!$H$6:$H$3665,$K22)) | I22: =IF(B22=B21,"",IF($K22="","",INDEX(Zeiterfassung!$I$6:$I$3665,MATCH(INDEX(Zeiterfassung!$K$6:$K$3665,$K22),Zeiterfassung!$K$6:$K$3665,0)))) | J22: =IF(B22=B21,"",IF($K22="","",INDEX(Zeiterfassung!$J$6:$J$3665,MATCH(INDEX(Zeiterfassung!$K$6:$K$3665,$K22),Zeiterfassung!$K$6:$K$3665,0)))) | K22: =IFERROR(AGGREGATE(15,6,(ROW(Zeiterfassung!$D$6:$D$3665)-ROW(Zeiterfassung!$D$6)+1)/(Zeiterfassung!$D$6:$D$3665<>""),17),"")
A23: =IF($K23="","",WEEKNUM(INDEX(Zeiterfassung!$K$6:$K$3665,$K23),21)) | B23: =IF($K23="","",INDEX(Zeiterfassung!$K$6:$K$3665,$K23)) | C23: =IF($K23="","",INDEX(Zeiterfassung!$K$6:$K$3665,$K23)) | D23: =IF($K23="","",INDEX(Zeiterfassung!$D$6:$D$3665,$K23)) | E23: =IF($K23="","",INDEX(Zeiterfassung!$E$6:$E$3665,$K23)) | F23: =IF($K23="","",INDEX(Zeiterfassung!$F$6:$F$3665,$K23)) | G23: =IF($K23="","",INDEX(Zeiterfassung!$G$6:$G$3665,$K23)) | H23: =IF($K23="","",INDEX(Zeiterfassung!$H$6:$H$3665,$K23)) | I23: =IF(B23=B22,"",IF($K23="","",INDEX(Zeiterfassung!$I$6:$I$3665,MATCH(INDEX(Zeiterfassung!$K$6:$K$3665,$K23),Zeiterfassung!$K$6:$K$3665,0)))) | J23: =IF(B23=B22,"",IF($K23="","",INDEX(Zeiterfassung!$J$6:$J$3665,MATCH(INDEX(Zeiterfassung!$K$6:$K$3665,$K23),Zeiterfassung!$K$6:$K$3665,0)))) | K23: =IFERROR(AGGREGATE(15,6,(ROW(Zeiterfassung!$D$6:$D$3665)-ROW(Zeiterfassung!$D$6)+1)/(Zeiterfassung!$D$6:$D$3665<>""),18),"")
A24: =IF($K24="","",WEEKNUM(INDEX(Zeiterfassung!$K$6:$K$3665,$K24),21)) | B24: =IF($K24="","",INDEX(Zeiterfassung!$K$6:$K$3665,$K24)) | C24: =IF($K24="","",INDEX(Zeiterfassung!$K$6:$K$3665,$K24)) | D24: =IF($K24="","",INDEX(Zeiterfassung!$D$6:$D$3665,$K24)) | E24: =IF($K24="","",INDEX(Zeiterfassung!$E$6:$E$3665,$K24)) | F24: =IF($K24="","",INDEX(Zeiterfassung!$F$6:$F$3665,$K24)) | G24: =IF($K24="","",INDEX(Zeiterfassung!$G$6:$G$3665,$K24)) | H24: =IF($K24="","",INDEX(Zeiterfassung!$H$6:$H$3665,$K24)) | I24: =IF(B24=B23,"",IF($K24="","",INDEX(Zeiterfassung!$I$6:$I$3665,MATCH(INDEX(Zeiterfassung!$K$6:$K$3665,$K24),Zeiterfassung!$K$6:$K$3665,0)))) | J24: =IF(B24=B23,"",IF($K24="","",INDEX(Zeiterfassung!$J$6:$J$3665,MATCH(INDEX(Zeiterfassung!$K$6:$K$3665,$K24),Zeiterfassung!$K$6:$K$3665,0)))) | K24: =IFERROR(AGGREGATE(15,6,(ROW(Zeiterfassung!$D$6:$D$3665)-ROW(Zeiterfassung!$D$6)+1)/(Zeiterfassung!$D$6:$D$3665<>""),19),"")
A25: =IF($K25="","",WEEKNUM(INDEX(Zeiterfassung!$K$6:$K$3665,$K25),21)) | B25: =IF($K25="","",INDEX(Zeiterfassung!$K$6:$K$3665,$K25)) | C25: =IF($K25="","",INDEX(Zeiterfassung!$K$6:$K$3665,$K25)) | D25: =IF($K25="","",INDEX(Zeiterfassung!$D$6:$D$3665,$K25)) | E25: =IF($K25="","",INDEX(Zeiterfassung!$E$6:$E$3665,$K25)) | F25: =IF($K25="","",INDEX(Zeiterfassung!$F$6:$F$3665,$K25)) | G25: =IF($K25="","",INDEX(Zeiterfassung!$G$6:$G$3665,$K25)) | H25: =IF($K25="","",INDEX(Zeiterfassung!$H$6:$H$3665,$K25)) | I25: =IF(B25=B24,"",IF($K25="","",INDEX(Zeiterfassung!$I$6:$I$3665,MATCH(INDEX(Zeiterfassung!$K$6:$K$3665,$K25),Zeiterfassung!$K$6:$K$3665,0)))) | J25: =IF(B25=B24,"",IF($K25="","",INDEX(Zeiterfassung!$J$6:$J$3665,MATCH(INDEX(Zeiterfassung!$K$6:$K$3665,$K25),Zeiterfassung!$K$6:$K$3665,0)))) | K25: =IFERROR(AGGREGATE(15,6,(ROW(Zeiterfassung!$D$6:$D$3665)-ROW(Zeiterfassung!$D$6)+1)/(Zeiterfassung!$D$6:$D$3665<>""),20),"")
A26: =IF($K26="","",WEEKNUM(INDEX(Zeiterfassung!$K$6:$K$3665,$K26),21)) | B26: =IF($K26="","",INDEX(Zeiterfassung!$K$6:$K$3665,$K26)) | C26: =IF($K26="","",INDEX(Zeiterfassung!$K$6:$K$3665,$K26)) | D26: =IF($K26="","",INDEX(Zeiterfassung!$D$6:$D$3665,$K26)) | E26: =IF($K26="","",INDEX(Zeiterfassung!$E$6:$E$3665,$K26)) | F26: =IF($K26="","",INDEX(Zeiterfassung!$F$6:$F$3665,$K26)) | G26: =IF($K26="","",INDEX(Zeiterfassung!$G$6:$G$3665,$K26)) | H26: =IF($K26="","",INDEX(Zeiterfassung!$H$6:$H$3665,$K26)) | I26: =IF(B26=B25,"",IF($K26="","",INDEX(Zeiterfassung!$I$6:$I$3665,MATCH(INDEX(Zeiterfassung!$K$6:$K$3665,$K26),Zeiterfassung!$K$6:$K$3665,0)))) | J26: =IF(B26=B25,"",IF($K26="","",INDEX(Zeiterfassung!$J$6:$J$3665,MATCH(INDEX(Zeiterfassung!$K$6:$K$3665,$K26),Zeiterfassung!$K$6:$K$3665,0)))) | K26: =IFERROR(AGGREGATE(15,6,(ROW(Zeiterfassung!$D$6:$D$3665)-ROW(Zeiterfassung!$D$6)+1)/(Zeiterfassung!$D$6:$D$3665<>""),21),"")
A27: =IF($K27="","",WEEKNUM(INDEX(Zeiterfassung!$K$6:$K$3665,$K27),21)) | B27: =IF($K27="","",INDEX(Zeiterfassung!$K$6:$K$3665,$K27)) | C27: =IF($K27="","",INDEX(Zeiterfassung!$K$6:$K$3665,$K27)) | D27: =IF($K27="","",INDEX(Zeiterfassung!$D$6:$D$3665,$K27)) | E27: =IF($K27="","",INDEX(Zeiterfassung!$E$6:$E$3665,$K27)) | F27: =IF($K27="","",INDEX(Zeiterfassung!$F$6:$F$3665,$K27)) | G27: =IF($K27="","",INDEX(Zeiterfassung!$G$6:$G$3665,$K27)) | H27: =IF($K27="","",INDEX(Zeiterfassung!$H$6:$H$3665,$K27)) | I27: =IF(B27=B26,"",IF($K27="","",INDEX(Zeiterfassung!$I$6:$I$3665,MATCH(INDEX(Zeiterfassung!$K$6:$K$3665,$K27),Zeiterfassung!$K$6:$K$3665,0)))) | J27: =IF(B27=B26,"",IF($K27="","",INDEX(Zeiterfassung!$J$6:$J$3665,MATCH(INDEX(Zeiterfassung!$K$6:$K$3665,$K27),Zeiterfassung!$K$6:$K$3665,0)))) | K27: =IFERROR(AGGREGATE(15,6,(ROW(Zeiterfassung!$D$6:$D$3665)-ROW(Zeiterfassung!$D$6)+1)/(Zeiterfassung!$D$6:$D$3665<>""),22),"")
A28: =IF($K28="","",WEEKNUM(INDEX(Zeiterfassung!$K$6:$K$3665,$K28),21)) | B28: =IF($K28="","",INDEX(Zeiterfassung!$K$6:$K$3665,$K28)) | C28: =IF($K28="","",INDEX(Zeiterfassung!$K$6:$K$3665,$K28)) | D28: =IF($K28="","",INDEX(Zeiterfassung!$D$6:$D$3665,$K28)) | E28: =IF($K28="","",INDEX(Zeiterfassung!$E$6:$E$3665,$K28)) | F28: =IF($K28="","",INDEX(Zeiterfassung!$F$6:$F$3665,$K28)) | G28: =IF($K28="","",INDEX(Zeiterfassung!$G$6:$G$3665,$K28)) | H28: =IF($K28="","",INDEX(Zeiterfassung!$H$6:$H$3665,$K28)) | I28: =IF(B28=B27,"",IF($K28="","",INDEX(Zeiterfassung!$I$6:$I$3665,MATCH(INDEX(Zeiterfassung!$K$6:$K$3665,$K28),Zeiterfassung!$K$6:$K$3665,0)))) | J28: =IF(B28=B27,"",IF($K28="","",INDEX(Zeiterfassung!$J$6:$J$3665,MATCH(INDEX(Zeiterfassung!$K$6:$K$3665,$K28),Zeiterfassung!$K$6:$K$3665,0)))) | K28: =IFERROR(AGGREGATE(15,6,(ROW(Zeiterfassung!$D$6:$D$3665)-ROW(Zeiterfassung!$D$6)+1)/(Zeiterfassung!$D$6:$D$3665<>""),23),"")
A29: =IF($K29="","",WEEKNUM(INDEX(Zeiterfassung!$K$6:$K$3665,$K29),21)) | B29: =IF($K29="","",INDEX(Zeiterfassung!$K$6:$K$3665,$K29)) | C29: =IF($K29="","",INDEX(Zeiterfassung!$K$6:$K$3665,$K29)) | D29: =IF($K29="","",INDEX(Zeiterfassung!$D$6:$D$3665,$K29)) | E29: =IF($K29="","",INDEX(Zeiterfassung!$E$6:$E$3665,$K29)) | F29: =IF($K29="","",INDEX(Zeiterfassung!$F$6:$F$3665,$K29)) | G29: =IF($K29="","",INDEX(Zeiterfassung!$G$6:$G$3665,$K29)) | H29: =IF($K29="","",INDEX(Zeiterfassung!$H$6:$H$3665,$K29)) | I29: =IF(B29=B28,"",IF($K29="","",INDEX(Zeiterfassung!$I$6:$I$3665,MATCH(INDEX(Zeiterfassung!$K$6:$K$3665,$K29),Zeiterfassung!$K$6:$K$3665,0)))) | J29: =IF(B29=B28,"",IF($K29="","",INDEX(Zeiterfassung!$J$6:$J$3665,MATCH(INDEX(Zeiterfassung!$K$6:$K$3665,$K29),Zeiterfassung!$K$6:$K$3665,0)))) | K29: =IFERROR(AGGREGATE(15,6,(ROW(Zeiterfassung!$D$6:$D$3665)-ROW(Zeiterfassung!$D$6)+1)/(Zeiterfassung!$D$6:$D$3665<>""),24),"")
A30: =IF($K30="","",WEEKNUM(INDEX(Zeiterfassung!$K$6:$K$3665,$K30),21)) | B30: =IF($K30="","",INDEX(Zeiterfassung!$K$6:$K$3665,$K30)) | C30: =IF($K30="","",INDEX(Zeiterfassung!$K$6:$K$3665,$K30)) | D30: =IF($K30="","",INDEX(Zeiterfassung!$D$6:$D$3665,$K30)) | E30: =IF($K30="","",INDEX(Zeiterfassung!$E$6:$E$3665,$K30)) | F30: =IF($K30="","",INDEX(Zeiterfassung!$F$6:$F$3665,$K30)) | G30: =IF($K30="","",INDEX(Zeiterfassung!$G$6:$G$3665,$K30)) | H30: =IF($K30="","",INDEX(Zeiterfassung!$H$6:$H$3665,$K30)) | I30: =IF(B30=B29,"",IF($K30="","",INDEX(Zeiterfassung!$I$6:$I$3665,MATCH(INDEX(Zeiterfassung!$K$6:$K$3665,$K30),Zeiterfassung!$K$6:$K$3665,0)))) | J30: =IF(B30=B29,"",IF($K30="","",INDEX(Zeiterfassung!$J$6:$J$3665,MATCH(INDEX(Zeiterfassung!$K$6:$K$3665,$K30),Zeiterfassung!$K$6:$K$3665,0)))) | K30: =IFERROR(AGGREGATE(15,6,(ROW(Zeiterfassung!$D$6:$D$3665)-ROW(Zeiterfassung!$D$6)+1)/(Zeiterfassung!$D$6:$D$3665<>""),25),"")
A31: =IF($K31="","",WEEKNUM(INDEX(Zeiterfassung!$K$6:$K$3665,$K31),21)) | B31: =IF($K31="","",INDEX(Zeiterfassung!$K$6:$K$3665,$K31)) | C31: =IF($K31="","",INDEX(Zeiterfassung!$K$6:$K$3665,$K31)) | D31: =IF($K31="","",INDEX(Zeiterfassung!$D$6:$D$3665,$K31)) | E31: =IF($K31="","",INDEX(Zeiterfassung!$E$6:$E$3665,$K31)) | F31: =IF($K31="","",INDEX(Zeiterfassung!$F$6:$F$3665,$K31)) | G31: =IF($K31="","",INDEX(Zeiterfassung!$G$6:$G$3665,$K31)) | H31: =IF($K31="","",INDEX(Zeiterfassung!$H$6:$H$3665,$K31)) | I31: =IF(B31=B30,"",IF($K31="","",INDEX(Zeiterfassung!$I$6:$I$3665,MATCH(INDEX(Zeiterfassung!$K$6:$K$3665,$K31),Zeiterfassung!$K$6:$K$3665,0)))) | J31: =IF(B31=B30,"",IF($K31="","",INDEX(Zeiterfassung!$J$6:$J$3665,MATCH(INDEX(Zeiterfassung!$K$6:$K$3665,$K31),Zeiterfassung!$K$6:$K$3665,0)))) | K31: =IFERROR(AGGREGATE(15,6,(ROW(Zeiterfassung!$D$6:$D$3665)-ROW(Zeiterfassung!$D$6)+1)/(Zeiterfassung!$D$6:$D$3665<>""),26),"")
A32: =IF($K32="","",WEEKNUM(INDEX(Zeiterfassung!$K$6:$K$3665,$K32),21)) | B32: =IF($K32="","",INDEX(Zeiterfassung!$K$6:$K$3665,$K32)) | C32: =IF($K32="","",INDEX(Zeiterfassung!$K$6:$K$3665,$K32)) | D32: =IF($K32="","",INDEX(Zeiterfassung!$D$6:$D$3665,$K32)) | E32: =IF($K32="","",INDEX(Zeiterfassung!$E$6:$E$3665,$K32)) | F32: =IF($K32="","",INDEX(Zeiterfassung!$F$6:$F$3665,$K32)) | G32: =IF($K32="","",INDEX(Zeiterfassung!$G$6:$G$3665,$K32)) | H32: =IF($K32="","",INDEX(Zeiterfassung!$H$6:$H$3665,$K32)) | I32: =IF(B32=B31,"",IF($K32="","",INDEX(Zeiterfassung!$I$6:$I$3665,MATCH(INDEX(Zeiterfassung!$K$6:$K$3665,$K32),Zeiterfassung!$K$6:$K$3665,0)))) | J32: =IF(B32=B31,"",IF($K32="","",INDEX(Zeiterfassung!$J$6:$J$3665,MATCH(INDEX(Zeiterfassung!$K$6:$K$3665,$K32),Zeiterfassung!$K$6:$K$3665,0)))) | K32: =IFERROR(AGGREGATE(15,6,(ROW(Zeiterfassung!$D$6:$D$3665)-ROW(Zeiterfassung!$D$6)+1)/(Zeiterfassung!$D$6:$D$3665<>""),27),"")
A33: =IF($K33="","",WEEKNUM(INDEX(Zeiterfassung!$K$6:$K$3665,$K33),21)) | B33: =IF($K33="","",INDEX(Zeiterfassung!$K$6:$K$3665,$K33)) | C33: =IF($K33="","",INDEX(Zeiterfassung!$K$6:$K$3665,$K33)) | D33: =IF($K33="","",INDEX(Zeiterfassung!$D$6:$D$3665,$K33)) | E33: =IF($K33="","",INDEX(Zeiterfassung!$E$6:$E$3665,$K33)) | F33: =IF($K33="","",INDEX(Zeiterfassung!$F$6:$F$3665,$K33)) | G33: =IF($K33="","",INDEX(Zeiterfassung!$G$6:$G$3665,$K33)) | H33: =IF($K33="","",INDEX(Zeiterfassung!$H$6:$H$3665,$K33)) | I33: =IF(B33=B32,"",IF($K33="","",INDEX(Zeiterfassung!$I$6:$I$3665,MATCH(INDEX(Zeiterfassung!$K$6:$K$3665,$K33),Zeiterfassung!$K$6:$K$3665,0)))) | J33: =IF(B33=B32,"",IF($K33="","",INDEX(Zeiterfassung!$J$6:$J$3665,MATCH(INDEX(Zeiterfassung!$K$6:$K$3665,$K33),Zeiterfassung!$K$6:$K$3665,0)))) | K33: =IFERROR(AGGREGATE(15,6,(ROW(Zeiterfassung!$D$6:$D$3665)-ROW(Zeiterfassung!$D$6)+1)/(Zeiterfassung!$D$6:$D$3665<>""),28),"")
A34: =IF($K34="","",WEEKNUM(INDEX(Zeiterfassung!$K$6:$K$3665,$K34),21)) | B34: =IF($K34="","",INDEX(Zeiterfassung!$K$6:$K$3665,$K34)) | C34: =IF($K34="","",INDEX(Zeiterfassung!$K$6:$K$3665,$K34)) | D34: =IF($K34="","",INDEX(Zeiterfassung!$D$6:$D$3665,$K34)) | E34: =IF($K34="","",INDEX(Zeiterfassung!$E$6:$E$3665,$K34)) | F34: =IF($K34="","",INDEX(Zeiterfassung!$F$6:$F$3665,$K34)) | G34: =IF($K34="","",INDEX(Zeiterfassung!$G$6:$G$3665,$K34)) | H34: =IF($K34="","",INDEX(Zeiterfassung!$H$6:$H$3665,$K34)) | I34: =IF(B34=B33,"",IF($K34="","",INDEX(Zeiterfassung!$I$6:$I$3665,MATCH(INDEX(Zeiterfassung!$K$6:$K$3665,$K34),Zeiterfassung!$K$6:$K$3665,0)))) | J34: =IF(B34=B33,"",IF($K34="","",INDEX(Zeiterfassung!$J$6:$J$3665,MATCH(INDEX(Zeiterfassung!$K$6:$K$3665,$K34),Zeiterfassung!$K$6:$K$3665,0)))) | K34: =IFERROR(AGGREGATE(15,6,(ROW(Zeiterfassung!$D$6:$D$3665)-ROW(Zeiterfassung!$D$6)+1)/(Zeiterfassung!$D$6:$D$3665<>""),29),"")
A35: =IF($K35="","",WEEKNUM(INDEX(Zeiterfassung!$K$6:$K$3665,$K35),21)) | B35: =IF($K35="","",INDEX(Zeiterfassung!$K$6:$K$3665,$K35)) | C35: =IF($K35="","",INDEX(Zeiterfassung!$K$6:$K$3665,$K35)) | D35: =IF($K35="","",INDEX(Zeiterfassung!$D$6:$D$3665,$K35)) | E35: =IF($K35="","",INDEX(Zeiterfassung!$E$6:$E$3665,$K35)) | F35: =IF($K35="","",INDEX(Zeiterfassung!$F$6:$F$3665,$K35)) | G35: =IF($K35="","",INDEX(Zeiterfassung!$G$6:$G$3665,$K35)) | H35: =IF($K35="","",INDEX(Zeiterfassung!$H$6:$H$3665,$K35)) | I35: =IF(B35=B34,"",IF($K35="","",INDEX(Zeiterfassung!$I$6:$I$3665,MATCH(INDEX(Zeiterfassung!$K$6:$K$3665,$K35),Zeiterfassung!$K$6:$K$3665,0)))) | J35: =IF(B35=B34,"",IF($K35="","",INDEX(Zeiterfassung!$J$6:$J$3665,MATCH(INDEX(Zeiterfassung!$K$6:$K$3665,$K35),Zeiterfassung!$K$6:$K$3665,0)))) | K35: =IFERROR(AGGREGATE(15,6,(ROW(Zeiterfassung!$D$6:$D$3665)-ROW(Zeiterfassung!$D$6)+1)/(Zeiterfassung!$D$6:$D$3665<>""),30),"")
A36: =IF($K36="","",WEEKNUM(INDEX(Zeiterfassung!$K$6:$K$3665,$K36),21)) | B36: =IF($K36="","",INDEX(Zeiterfassung!$K$6:$K$3665,$K36)) | C36: =IF($K36="","",INDEX(Zeiterfassung!$K$6:$K$3665,$K36)) | D36: =IF($K36="","",INDEX(Zeiterfassung!$D$6:$D$3665,$K36)) | E36: =IF($K36="","",INDEX(Zeiterfassung!$E$6:$E$3665,$K36)) | F36: =IF($K36="","",INDEX(Zeiterfassung!$F$6:$F$3665,$K36)) | G36: =IF($K36="","",INDEX(Zeiterfassung!$G$6:$G$3665,$K36)) | H36: =IF($K36="","",INDEX(Zeiterfassung!$H$6:$H$3665,$K36)) | I36: =IF(B36=B35,"",IF($K36="","",INDEX(Zeiterfassung!$I$6:$I$3665,MATCH(INDEX(Zeiterfassung!$K$6:$K$3665,$K36),Zeiterfassung!$K$6:$K$3665,0)))) | J36: =IF(B36=B35,"",IF($K36="","",INDEX(Zeiterfassung!$J$6:$J$3665,MATCH(INDEX(Zeiterfassung!$K$6:$K$3665,$K36),Zeiterfassung!$K$6:$K$3665,0)))) | K36: =IFERROR(AGGREGATE(15,6,(ROW(Zeiterfassung!$D$6:$D$3665)-ROW(Zeiterfassung!$D$6)+1)/(Zeiterfassung!$D$6:$D$3665<>""),31),"")
A37: =IF($K37="","",WEEKNUM(INDEX(Zeiterfassung!$K$6:$K$3665,$K37),21)) | B37: =IF($K37="","",INDEX(Zeiterfassung!$K$6:$K$3665,$K37)) | C37: =IF($K37="","",INDEX(Zeiterfassung!$K$6:$K$3665,$K37)) | D37: =IF($K37="","",INDEX(Zeiterfassung!$D$6:$D$3665,$K37)) | E37: =IF($K37="","",INDEX(Zeiterfassung!$E$6:$E$3665,$K37)) | F37: =IF($K37="","",INDEX(Zeiterfassung!$F$6:$F$3665,$K37)) | G37: =IF($K37="","",INDEX(Zeiterfassung!$G$6:$G$3665,$K37)) | H37: =IF($K37="","",INDEX(Zeiterfassung!$H$6:$H$3665,$K37)) | I37: =IF(B37=B36,"",IF($K37="","",INDEX(Zeiterfassung!$I$6:$I$3665,MATCH(INDEX(Zeiterfassung!$K$6:$K$3665,$K37),Zeiterfassung!$K$6:$K$3665,0)))) | J37: =IF(B37=B36,"",IF($K37="","",INDEX(Zeiterfassung!$J$6:$J$3665,MATCH(INDEX(Zeiterfassung!$K$6:$K$3665,$K37),Zeiterfassung!$K$6:$K$3665,0)))) | K37: =IFERROR(AGGREGATE(15,6,(ROW(Zeiterfassung!$D$6:$D$3665)-ROW(Zeiterfassung!$D$6)+1)/(Zeiterfassung!$D$6:$D$3665<>""),32),"")
A38: =IF($K38="","",WEEKNUM(INDEX(Zeiterfassung!$K$6:$K$3665,$K38),21)) | B38: =IF($K38="","",INDEX(Zeiterfassung!$K$6:$K$3665,$K38)) | C38: =IF($K38="","",INDEX(Zeiterfassung!$K$6:$K$3665,$K38)) | D38: =IF($K38="","",INDEX(Zeiterfassung!$D$6:$D$3665,$K38)) | E38: =IF($K38="","",INDEX(Zeiterfassung!$E$6:$E$3665,$K38)) | F38: =IF($K38="","",INDEX(Zeiterfassung!$F$6:$F$3665,$K38)) | G38: =IF($K38="","",INDEX(Zeiterfassung!$G$6:$G$3665,$K38)) | H38: =IF($K38="","",INDEX(Zeiterfassung!$H$6:$H$3665,$K38)) | I38: =IF(B38=B37,"",IF($K38="","",INDEX(Zeiterfassung!$I$6:$I$3665,MATCH(INDEX(Zeiterfassung!$K$6:$K$3665,$K38),Zeiterfassung!$K$6:$K$3665,0)))) | J38: =IF(B38=B37,"",IF($K38="","",INDEX(Zeiterfassung!$J$6:$J$3665,MATCH(INDEX(Zeiterfassung!$K$6:$K$3665,$K38),Zeiterfassung!$K$6:$K$3665,0)))) | K38: =IFERROR(AGGREGATE(15,6,(ROW(Zeiterfassung!$D$6:$D$3665)-ROW(Zeiterfassung!$D$6)+1)/(Zeiterfassung!$D$6:$D$3665<>""),33),"")
A39: =IF($K39="","",WEEKNUM(INDEX(Zeiterfassung!$K$6:$K$3665,$K39),21)) | B39: =IF($K39="","",INDEX(Zeiterfassung!$K$6:$K$3665,$K39)) | C39: =IF($K39="","",INDEX(Zeiterfassung!$K$6:$K$3665,$K39)) | D39: =IF($K39="","",INDEX(Zeiterfassung!$D$6:$D$3665,$K39)) | E39: =IF($K39="","",INDEX(Zeiterfassung!$E$6:$E$3665,$K39)) | F39: =IF($K39="","",INDEX(Zeiterfassung!$F$6:$F$3665,$K39)) | G39: =IF($K39="","",INDEX(Zeiterfassung!$G$6:$G$3665,$K39)) | H39: =IF($K39="","",INDEX(Zeiterfassung!$H$6:$H$3665,$K39)) | I39: =IF(B39=B38,"",IF($K39="","",INDEX(Zeiterfassung!$I$6:$I$3665,MATCH(INDEX(Zeiterfassung!$K$6:$K$3665,$K39),Zeiterfassung!$K$6:$K$3665,0)))) | J39: =IF(B39=B38,"",IF($K39="","",INDEX(Zeiterfassung!$J$6:$J$3665,MATCH(INDEX(Zeiterfassung!$K$6:$K$3665,$K39),Zeiterfassung!$K$6:$K$3665,0)))) | K39: =IFERROR(AGGREGATE(15,6,(ROW(Zeiterfassung!$D$6:$D$3665)-ROW(Zeiterfassung!$D$6)+1)/(Zeiterfassung!$D$6:$D$3665<>""),34),"")
A40: =IF($K40="","",WEEKNUM(INDEX(Zeiterfassung!$K$6:$K$3665,$K40),21)) | B40: =IF($K40="","",INDEX(Zeiterfassung!$K$6:$K$3665,$K40)) | C40: =IF($K40="","",INDEX(Zeiterfassung!$K$6:$K$3665,$K40)) | D40: =IF($K40="","",INDEX(Zeiterfassung!$D$6:$D$3665,$K40)) | E40: =IF($K40="","",INDEX(Zeiterfassung!$E$6:$E$3665,$K40)) | F40: =IF($K40="","",INDEX(Zeiterfassung!$F$6:$F$3665,$K40)) | G40: =IF($K40="","",INDEX(Zeiterfassung!$G$6:$G$3665,$K40)) | H40: =IF($K40="","",INDEX(Zeiterfassung!$H$6:$H$3665,$K40)) | I40: =IF(B40=B39,"",IF($K40="","",INDEX(Zeiterfassung!$I$6:$I$3665,MATCH(INDEX(Zeiterfassung!$K$6:$K$3665,$K40),Zeiterfassung!$K$6:$K$3665,0)))) | J40: =IF(B40=B39,"",IF($K40="","",INDEX(Zeiterfassung!$J$6:$J$3665,MATCH(INDEX(Zeiterfassung!$K$6:$K$3665,$K40),Zeiterfassung!$K$6:$K$3665,0)))) | K40: =IFERROR(AGGREGATE(15,6,(ROW(Zeiterfassung!$D$6:$D$3665)-ROW(Zeiterfassung!$D$6)+1)/(Zeiterfassung!$D$6:$D$3665<>""),35),"")
A41: =IF($K41="","",WEEKNUM(INDEX(Zeiterfassung!$K$6:$K$3665,$K41),21)) | B41: =IF($K41="","",INDEX(Zeiterfassung!$K$6:$K$3665,$K41)) | C41: =IF($K41="","",INDEX(Zeiterfassung!$K$6:$K$3665,$K41)) | D41: =IF($K41="","",INDEX(Zeiterfassung!$D$6:$D$3665,$K41)) | E41: =IF($K41="","",INDEX(Zeiterfassung!$E$6:$E$3665,$K41)) | F41: =IF($K41="","",INDEX(Zeiterfassung!$F$6:$F$3665,$K41)) | G41: =IF($K41="","",INDEX(Zeiterfassung!$G$6:$G$3665,$K41)) | H41: =IF($K41="","",INDEX(Zeiterfassung!$H$6:$H$3665,$K41)) | I41: =IF(B41=B40,"",IF($K41="","",INDEX(Zeiterfassung!$I$6:$I$3665,MATCH(INDEX(Zeiterfassung!$K$6:$K$3665,$K41),Zeiterfassung!$K$6:$K$3665,0)))) | J41: =IF(B41=B40,"",IF($K41="","",INDEX(Zeiterfassung!$J$6:$J$3665,MATCH(INDEX(Zeiterfassung!$K$6:$K$3665,$K41),Zeiterfassung!$K$6:$K$3665,0)))) | K41: =IFERROR(AGGREGATE(15,6,(ROW(Zeiterfassung!$D$6:$D$3665)-ROW(Zeiterfassung!$D$6)+1)/(Zeiterfassung!$D$6:$D$3665<>""),36),"")
...

Sheet Materialkosten
A1: MATERIALKOSTEN | H1: ← ZUM COCKPIT
A3: Fortlaufende Erfassung der projektbezogenen Material- und Sachkosten · Nachunternehmer separat erfassen
A5: Datum | B5: Lieferant | C5: Rechnung / Beleg-Nr. | D5: Beschreibung | E5: Nettobetrag | F5: Bemerkung

Sheet Rechnungsstand
A1: RECHNUNGSSTAND | O1: ← ZUM COCKPIT
K2: PROJEKTFORTSCHRITT
A3: Fortlaufende Erfassung von Abschlags-, Teilschluss- und Schlussrechnungen | K3: Auftragssumme netto | M3: ='Projektübersicht'!$B$28
K4: In Rechnung gestellt netto | M4: =SUM($F$6:$F$305)
A5: Rechnungsdatum | B5: Rechnungsnummer | C5: Rechnungsart | D5: Leistungszeitraum | E5: Leistungsstand / Bezeichnung | F5: Rechnungsbetrag netto (diese Rechnung) | G5: Zahlungseingang | H5: Offener Betrag | I5: Bemerkung | K5: Unfertige Leistungen netto
H6: =IF(F6="","",F6-IF(G6="",0,G6)) | K6: Leistungsstand gesamt | M6: =SUM(M4:M5)
H7: =IF(F7="","",F7-IF(G7="",0,G7)) | K7: Restleistung | M7: =MAX(0,M3-M6)
H8: =IF(F8="","",F8-IF(G8="",0,G8)) | K8: Projektfortschritt | M8: =IF(M3>0,M6/M3,"")
H9: =IF(F9="","",F9-IF(G9="",0,G9)) | K9: Hinweis: Unfertige Leistungen werden manuell zum jeweiligen Stichtag bewertet.
H10: =IF(F10="","",F10-IF(G10="",0,G10))
H11: =IF(F11="","",F11-IF(G11="",0,G11)) | K11: RECHNUNGSPRÜFUNG
H12: =IF(F12="","",F12-IF(G12="",0,G12)) | K12: → PRÜFBLATT ÖFFNEN
H13: =IF(F13="","",F13-IF(G13="",0,G13))
H14: =IF(F14="","",F14-IF(G14="",0,G14))
H15: =IF(F15="","",F15-IF(G15="",0,G15))
H16: =IF(F16="","",F16-IF(G16="",0,G16))
H17: =IF(F17="","",F17-IF(G17="",0,G17))
H18: =IF(F18="","",F18-IF(G18="",0,G18))
H19: =IF(F19="","",F19-IF(G19="",0,G19))
H20: =IF(F20="","",F20-IF(G20="",0,G20))
H21: =IF(F21="","",F21-IF(G21="",0,G21))
H22: =IF(F22="","",F22-IF(G22="",0,G22))
H23: =IF(F23="","",F23-IF(G23="",0,G23))
H24: =IF(F24="","",F24-IF(G24="",0,G24))
... H305: =IF(F305="","",F305-IF(G305="",0,G305))

Sheet Rechnungsprüfung
A1: RECHNUNGSPRÜFUNG · VOB/B-ORIENTIERTE ABSTIMMUNG
A3: Fortlaufender Soll-/Ist-Abgleich zwischen eigener Rechnungsstellung und den Prüfblättern des Auftraggebers | U3: ← ZUM COCKPIT
A5: VERTRAGLICHE PRÜFPARAMETER | G5: KUMULIERTER ABRECHNUNGSSTAND
A6: Auftragssumme netto | B6: ='Projektübersicht'!$B$28 | G6: AN Rechnungen netto | J6: =SUM($D$12:$D$311) | L6: Vertragliche Einbehalte Soll | O6: =SUM($J$12:$J$311) | Q6: Erwartet zahlbar | T6: =SUM($K$12:$K$311)
A7: Baustrom | B7: 0 | D7: Vertragserfüllung · Einbehalt je Abschlag | E7: 0.1 | G7: AG anerkannt netto | J7: =SUM($N$12:$N$311) | L7: AG Einbehalte / Kürzungen | O7: =SUM($S$12:$S$311) | Q7: AG geprüft zahlbar | T7: =SUM($T$12:$T$311)
A8: Versicherung | B8: 0 | D8: Vertragserfüllung · Sicherungsziel | E8: 0 | G8: Differenz Leistungsstand | J8: =J6-J7 | L8: Differenz Einbehalte | O8: =O7-O6 | Q8: Differenz zahlbar | T8: =T7-T6
A9: Infrastruktur | B9: 0 | D9: Mängelanspruchssicherheit (optional) | E9: 0 | L9: Blau = Werte aus dem Prüfblatt des Auftraggebers manuell übernehmen
A10: EIGENE RECHNUNG / ERWARTETE PRÜFUNG | L10: PRÜFBLATT AUFTRAGGEBER · MANUELLE ÜBERNAHME | U10: ABWEICHUNG / KLÄRUNG
A11: Rechnungsdatum | B11: Rechnungsnummer | C11: Rechnungsart | D11: AN Rechnung netto | E11: Kumuliert AN netto | F11: Baustrom Soll | G11: Versicherung Soll | H11: Infrastruktur Soll | I11: VE-Sicherheit Soll | J11: Einbehalte Soll gesamt | K11: Erwartet zahlbar | L11: AG Prüfblatt-Nr. | M11: AG Prüfdatum | N11: AG anerkannt netto | O11: AG Baustrom | P11: AG Versicherung | Q11: AG Infrastruktur | R11: AG VE-Sicherheit | S11: AG Einbehalte gesamt | T11: AG geprüft zahlbar | U11: Diff. Leistung | V11: Diff. zahlbar | W11: Bemerkung / Klärung
A12: =IF(Rechnungsstand!B6="","",Rechnungsstand!A6) | B12: =IF(Rechnungsstand!B6="","",Rechnungsstand!B6) | C12: =IF(Rechnungsstand!B6="","",Rechnungsstand!C6) | D12: =IF(Rechnungsstand!B6="","",Rechnungsstand!F6) | E12: =IF(D12="","",SUM($D$12:D12)) | F12: =IF(D12="","",D12*$B$7) | G12: =IF(D12="","",D12*$B$8) | H12: =IF(D12="","",D12*$B$9) | I12: =IF(D12="","",IF(C12="Abschlagsrechnung",MAX(0,MIN(D12*$E$7,IF($E$8>0,$B$6*$E$8-0,D12*$E$7))),0)) | J12: =IF(D12="","",SUM(F12:I12)) | K12: =IF(D12="","",D12-J12) | S12: =IF(COUNTA(O12:R12)=0,"",SUM(O12:R12)) | T12: =IF(N12="","",N12-IF(S12="",0,S12)) | U12: =IF(OR(D12="",N12=""),"",N12-D12) | V12: =IF(OR(K12="",T12=""),"",T12-K12)
A13: =IF(Rechnungsstand!B7="","",Rechnungsstand!A7) | B13: =IF(Rechnungsstand!B7="","",Rechnungsstand!B7) | C13: =IF(Rechnungsstand!B7="","",Rechnungsstand!C7) | D13: =IF(Rechnungsstand!B7="","",Rechnungsstand!F7) | E13: =IF(D13="","",SUM($D$12:D13)) | F13: =IF(D13="","",D13*$B$7) | G13: =IF(D13="","",D13*$B$8) | H13: =IF(D13="","",D13*$B$9) | I13: =IF(D13="","",IF(C13="Abschlagsrechnung",MAX(0,MIN(D13*$E$7,IF($E$8>0,$B$6*$E$8-SUM($I$12:I12),D13*$E$7))),0)) | J13: =IF(D13="","",SUM(F13:I13)) | K13: =IF(D13="","",D13-J13) | S13: =IF(COUNTA(O13:R13)=0,"",SUM(O13:R13)) | T13: =IF(N13="","",N13-IF(S13="",0,S13)) | U13: =IF(OR(D13="",N13=""),"",N13-D13) | V13: =IF(OR(K13="",T13=""),"",T13-K13)
A14: =IF(Rechnungsstand!B8="","",Rechnungsstand!A8) | B14: =IF(Rechnungsstand!B8="","",Rechnungsstand!B8) | C14: =IF(Rechnungsstand!B8="","",Rechnungsstand!C8) | D14: =IF(Rechnungsstand!B8="","",Rechnungsstand!F8) | E14: =IF(D14="","",SUM($D$12:D14)) | F14: =IF(D14="","",D14*$B$7) | G14: =IF(D14="","",D14*$B$8) | H14: =IF(D14="","",D14*$B$9) | I14: =IF(D14="","",IF(C14="Abschlagsrechnung",MAX(0,MIN(D14*$E$7,IF($E$8>0,$B$6*$E$8-SUM($I$12:I13),D14*$E$7))),0)) | J14: =IF(D14="","",SUM(F14:I14)) | K14: =IF(D14="","",D14-J14) | S14: =IF(COUNTA(O14:R14)=0,"",SUM(O14:R14)) | T14: =IF(N14="","",N14-IF(S14="",0,S14)) | U14: =IF(OR(D14="",N14=""),"",N14-D14) | V14: =IF(OR(K14="",T14=""),"",T14-K14)
A15: =IF(Rechnungsstand!B9="","",Rechnungsstand!A9) | B15: =IF(Rechnungsstand!B9="","",Rechnungsstand!B9) | C15: =IF(Rechnungsstand!B9="","",Rechnungsstand!C9) | D15: =IF(Rechnungsstand!B9="","",Rechnungsstand!F9) | E15: =IF(D15="","",SUM($D$12:D15)) | F15: =IF(D15="","",D15*$B$7) | G15: =IF(D15="","",D15*$B$8) | H15: =IF(D15="","",D15*$B$9) | I15: =IF(D15="","",IF(C15="Abschlagsrechnung",MAX(0,MIN(D15*$E$7,IF($E$8>0,$B$6*$E$8-SUM($I$12:I14),D15*$E$7))),0)) | J15: =IF(D15="","",SUM(F15:I15)) | K15: =IF(D15="","",D15-J15) | S15: =IF(COUNTA(O15:R15)=0,"",SUM(O15:R15)) | T15: =IF(N15="","",N15-IF(S15="",0,S15)) | U15: =IF(OR(D15="",N15=""),"",N15-D15) | V15: =IF(OR(K15="",T15=""),"",T15-K15)
A16: =IF(Rechnungsstand!B10="","",Rechnungsstand!A10) | B16: =IF(Rechnungsstand!B10="","",Rechnungsstand!B10) | C16: =IF(Rechnungsstand!B10="","",Rechnungsstand!C10) | D16: =IF(Rechnungsstand!B10="","",Rechnungsstand!F10) | E16: =IF(D16="","",SUM($D$12:D16)) | F16: =IF(D16="","",D16*$B$7) | G16: =IF(D16="","",D16*$B$8) | H16: =IF(D16="","",D16*$B$9) | I16: =IF(D16="","",IF(C16="Abschlagsrechnung",MAX(0,MIN(D16*$E$7,IF($E$8>0,$B$6*$E$8-SUM($I$12:I15),D16*$E$7))),0)) | J16: =IF(D16="","",SUM(F16:I16)) | K16: =IF(D16="","",D16-J16) | S16: =IF(COUNTA(O16:R16)=0,"",SUM(O16:R16)) | T16: =IF(N16="","",N16-IF(S16="",0,S16)) | U16: =IF(OR(D16="",N16=""),"",N16-D16) | V16: =IF(OR(K16="",T16=""),"",T16-K16)
A17: =IF(Rechnungsstand!B11="","",Rechnungsstand!A11) | B17: =IF(Rechnungsstand!B11="","",Rechnungsstand!B11) | C17: =IF(Rechnungsstand!B11="","",Rechnungsstand!C11) | D17: =IF(Rechnungsstand!B11="","",Rechnungsstand!F11) | E17: =IF(D17="","",SUM($D$12:D17)) | F17: =IF(D17="","",D17*$B$7) | G17: =IF(D17="","",D17*$B$8) | H17: =IF(D17="","",D17*$B$9) | I17: =IF(D17="","",IF(C17="Abschlagsrechnung",MAX(0,MIN(D17*$E$7,IF($E$8>0,$B$6*$E$8-SUM($I$12:I16),D17*$E$7))),0)) | J17: =IF(D17="","",SUM(F17:I17)) | K17: =IF(D17="","",D17-J17) | S17: =IF(COUNTA(O17:R17)=0,"",SUM(O17:R17)) | T17: =IF(N17="","",N17-IF(S17="",0,S17)) | U17: =IF(OR(D17="",N17=""),"",N17-D17) | V17: =IF(OR(K17="",T17=""),"",T17-K17)
A18: =IF(Rechnungsstand!B12="","",Rechnungsstand!A12) | B18: =IF(Rechnungsstand!B12="","",Rechnungsstand!B12) | C18: =IF(Rechnungsstand!B12="","",Rechnungsstand!C12) | D18: =IF(Rechnungsstand!B12="","",Rechnungsstand!F12) | E18: =IF(D18="","",SUM($D$12:D18)) | F18: =IF(D18="","",D18*$B$7) | G18: =IF(D18="","",D18*$B$8) | H18: =IF(D18="","",D18*$B$9) | I18: =IF(D18="","",IF(C18="Abschlagsrechnung",MAX(0,MIN(D18*$E$7,IF($E$8>0,$B$6*$E$8-SUM($I$12:I17),D18*$E$7))),0)) | J18: =IF(D18="","",SUM(F18:I18)) | K18: =IF(D18="","",D18-J18) | S18: =IF(COUNTA(O18:R18)=0,"",SUM(O18:R18)) | T18: =IF(N18="","",N18-IF(S18="",0,S18)) | U18: =IF(OR(D18="",N18=""),"",N18-D18) | V18: =IF(OR(K18="",T18=""),"",T18-K18)
A19: =IF(Rechnungsstand!B13="","",Rechnungsstand!A13) | B19: =IF(Rechnungsstand!B13="","",Rechnungsstand!B13) | C19: =IF(Rechnungsstand!B13="","",Rechnungsstand!C13) | D19: =IF(Rechnungsstand!B13="","",Rechnungsstand!F13) | E19: =IF(D19="","",SUM($D$12:D19)) | F19: =IF(D19="","",D19*$B$7) | G19: =IF(D19="","",D19*$B$8) | H19: =IF(D19="","",D19*$B$9) | I19: =IF(D19="","",IF(C19="Abschlagsrechnung",MAX(0,MIN(D19*$E$7,IF($E$8>0,$B$6*$E$8-SUM($I$12:I18),D19*$E$7))),0)) | J19: =IF(D19="","",SUM(F19:I19)) | K19: =IF(D19="","",D19-J19) | S19: =IF(COUNTA(O19:R19)=0,"",SUM(O19:R19)) | T19: =IF(N19="","",N19-IF(S19="",0,S19)) | U19: =IF(OR(D19="",N19=""),"",N19-D19) | V19: =IF(OR(K19="",T19=""),"",T19-K19)
A20: =IF(Rechnungsstand!B14="","",Rechnungsstand!A14) | B20: =IF(Rechnungsstand!B14="","",Rechnungsstand!B14) | C20: =IF(Rechnungsstand!B14="","",Rechnungsstand!C14) | D20: =IF(Rechnungsstand!B14="","",Rechnungsstand!F14) | E20: =IF(D20="","",SUM($D$12:D20)) | F20: =IF(D20="","",D20*$B$7) | G20: =IF(D20="","",D20*$B$8) | H20: =IF(D20="","",D20*$B$9) | I20: =IF(D20="","",IF(C20="Abschlagsrechnung",MAX(0,MIN(D20*$E$7,IF($E$8>0,$B$6*$E$8-SUM($I$12:I19),D20*$E$7))),0)) | J20: =IF(D20="","",SUM(F20:I20)) | K20: =IF(D20="","",D20-J20) | S20: =IF(COUNTA(O20:R20)=0,"",SUM(O20:R20)) | T20: =IF(N20="","",N20-IF(S20="",0,S20)) | U20: =IF(OR(D20="",N20=""),"",N20-D20) | V20: =IF(OR(K20="",T20=""),"",T20-K20)
A21: =IF(Rechnungsstand!B15="","",Rechnungsstand!A15) | B21: =IF(Rechnungsstand!B15="","",Rechnungsstand!B15) | C21: =IF(Rechnungsstand!B15="","",Rechnungsstand!C15) | D21: =IF(Rechnungsstand!B15="","",Rechnungsstand!F15) | E21: =IF(D21="","",SUM($D$12:D21)) | F21: =IF(D21="","",D21*$B$7) | G21: =IF(D21="","",D21*$B$8) | H21: =IF(D21="","",D21*$B$9) | I21: =IF(D21="","",IF(C21="Abschlagsrechnung",MAX(0,MIN(D21*$E$7,IF($E$8>0,$B$6*$E$8-SUM($I$12:I20),D21*$E$7))),0)) | J21: =IF(D21="","",SUM(F21:I21)) | K21: =IF(D21="","",D21-J21) | S21: =IF(COUNTA(O21:R21)=0,"",SUM(O21:R21)) | T21: =IF(N21="","",N21-IF(S21="",0,S21)) | U21: =IF(OR(D21="",N21=""),"",N21-D21) | V21: =IF(OR(K21="",T21=""),"",T21-K21)
